[2024-07-04T12:35:49.158+0530] {local_task_job_runner.py:120} INFO - ::group::Pre task execution logs
[2024-07-04T12:35:49.170+0530] {taskinstance.py:2076} INFO - Dependencies all met for dep_context=non-requeueable deps ti=<TaskInstance: data_transformation.data_extraction scheduled__2024-07-03T00:00:00+00:00 [queued]>
[2024-07-04T12:35:49.177+0530] {taskinstance.py:2076} INFO - Dependencies all met for dep_context=requeueable deps ti=<TaskInstance: data_transformation.data_extraction scheduled__2024-07-03T00:00:00+00:00 [queued]>
[2024-07-04T12:35:49.177+0530] {taskinstance.py:2306} INFO - Starting attempt 2 of 2
[2024-07-04T12:35:49.192+0530] {taskinstance.py:2330} INFO - Executing <Task(HttpOperator): data_extraction> on 2024-07-03 00:00:00+00:00
[2024-07-04T12:35:49.194+0530] {standard_task_runner.py:63} INFO - Started process 90889 to run task
[2024-07-04T12:35:49.198+0530] {standard_task_runner.py:90} INFO - Running: ['airflow', 'tasks', 'run', 'data_transformation', 'data_extraction', 'scheduled__2024-07-03T00:00:00+00:00', '--job-id', '3', '--raw', '--subdir', 'DAGS_FOLDER/etl.py', '--cfg-path', '/tmp/tmpi076uzt1']
[2024-07-04T12:35:49.200+0530] {standard_task_runner.py:91} INFO - Job 3: Subtask data_extraction
[2024-07-04T12:35:49.236+0530] {task_command.py:426} INFO - Running <TaskInstance: data_transformation.data_extraction scheduled__2024-07-03T00:00:00+00:00 [running]> on host ongraph-Lenovo-V130-14IKB
[2024-07-04T12:35:49.301+0530] {taskinstance.py:2648} INFO - Exporting env vars: AIRFLOW_CTX_DAG_OWNER='rohit' AIRFLOW_CTX_DAG_ID='data_transformation' AIRFLOW_CTX_TASK_ID='data_extraction' AIRFLOW_CTX_EXECUTION_DATE='2024-07-03T00:00:00+00:00' AIRFLOW_CTX_TRY_NUMBER='2' AIRFLOW_CTX_DAG_RUN_ID='scheduled__2024-07-03T00:00:00+00:00'
[2024-07-04T12:35:49.302+0530] {taskinstance.py:430} INFO - ::endgroup::
[2024-07-04T12:35:49.317+0530] {http.py:169} INFO - Calling HTTP method
[2024-07-04T12:35:49.322+0530] {base.py:84} INFO - Using connection ID 'http_connection' for task execution.
[2024-07-04T12:35:49.344+0530] {base.py:84} INFO - Using connection ID 'http_connection' for task execution.
[2024-07-04T12:35:49.347+0530] {http.py:243} WARNING - HTTPConnectionPool(host='https', port=80): Max retries exceeded with url: //chroniclingamerica.loc.gov/newspapers.json (Caused by NewConnectionError('<urllib3.connection.HTTPConnection object at 0x7611ecc48b50>: Failed to establish a new connection: [Errno -3] Temporary failure in name resolution')) Tenacity will retry to execute the operation
[2024-07-04T12:35:49.347+0530] {taskinstance.py:441} INFO - ::group::Post task execution logs
[2024-07-04T12:35:49.347+0530] {taskinstance.py:2905} ERROR - Task failed with exception
Traceback (most recent call last):
  File "/home/ongraph/Desktop/airflow/airflow_ETL/venv/lib/python3.10/site-packages/urllib3/connection.py", line 174, in _new_conn
    conn = connection.create_connection(
  File "/home/ongraph/Desktop/airflow/airflow_ETL/venv/lib/python3.10/site-packages/urllib3/util/connection.py", line 72, in create_connection
    for res in socket.getaddrinfo(host, port, family, socket.SOCK_STREAM):
  File "/usr/lib/python3.10/socket.py", line 955, in getaddrinfo
    for res in _socket.getaddrinfo(host, port, family, type, proto, flags):
socket.gaierror: [Errno -3] Temporary failure in name resolution

During handling of the above exception, another exception occurred:

Traceback (most recent call last):
  File "/home/ongraph/Desktop/airflow/airflow_ETL/venv/lib/python3.10/site-packages/urllib3/connectionpool.py", line 715, in urlopen
    httplib_response = self._make_request(
  File "/home/ongraph/Desktop/airflow/airflow_ETL/venv/lib/python3.10/site-packages/urllib3/connectionpool.py", line 416, in _make_request
    conn.request(method, url, **httplib_request_kw)
  File "/home/ongraph/Desktop/airflow/airflow_ETL/venv/lib/python3.10/site-packages/urllib3/connection.py", line 244, in request
    super(HTTPConnection, self).request(method, url, body=body, headers=headers)
  File "/usr/lib/python3.10/http/client.py", line 1283, in request
    self._send_request(method, url, body, headers, encode_chunked)
  File "/usr/lib/python3.10/http/client.py", line 1329, in _send_request
    self.endheaders(body, encode_chunked=encode_chunked)
  File "/usr/lib/python3.10/http/client.py", line 1278, in endheaders
    self._send_output(message_body, encode_chunked=encode_chunked)
  File "/usr/lib/python3.10/http/client.py", line 1038, in _send_output
    self.send(msg)
  File "/usr/lib/python3.10/http/client.py", line 976, in send
    self.connect()
  File "/home/ongraph/Desktop/airflow/airflow_ETL/venv/lib/python3.10/site-packages/urllib3/connection.py", line 205, in connect
    conn = self._new_conn()
  File "/home/ongraph/Desktop/airflow/airflow_ETL/venv/lib/python3.10/site-packages/urllib3/connection.py", line 186, in _new_conn
    raise NewConnectionError(
urllib3.exceptions.NewConnectionError: <urllib3.connection.HTTPConnection object at 0x7611ecc48b50>: Failed to establish a new connection: [Errno -3] Temporary failure in name resolution

During handling of the above exception, another exception occurred:

Traceback (most recent call last):
  File "/home/ongraph/Desktop/airflow/airflow_ETL/venv/lib/python3.10/site-packages/requests/adapters.py", line 486, in send
    resp = conn.urlopen(
  File "/home/ongraph/Desktop/airflow/airflow_ETL/venv/lib/python3.10/site-packages/urllib3/connectionpool.py", line 799, in urlopen
    retries = retries.increment(
  File "/home/ongraph/Desktop/airflow/airflow_ETL/venv/lib/python3.10/site-packages/urllib3/util/retry.py", line 592, in increment
    raise MaxRetryError(_pool, url, error or ResponseError(cause))
urllib3.exceptions.MaxRetryError: HTTPConnectionPool(host='https', port=80): Max retries exceeded with url: //chroniclingamerica.loc.gov/newspapers.json (Caused by NewConnectionError('<urllib3.connection.HTTPConnection object at 0x7611ecc48b50>: Failed to establish a new connection: [Errno -3] Temporary failure in name resolution'))

During handling of the above exception, another exception occurred:

Traceback (most recent call last):
  File "/home/ongraph/Desktop/airflow/airflow_ETL/venv/lib/python3.10/site-packages/airflow/models/taskinstance.py", line 465, in _execute_task
    result = _execute_callable(context=context, **execute_callable_kwargs)
  File "/home/ongraph/Desktop/airflow/airflow_ETL/venv/lib/python3.10/site-packages/airflow/models/taskinstance.py", line 432, in _execute_callable
    return execute_callable(context=context, **execute_callable_kwargs)
  File "/home/ongraph/Desktop/airflow/airflow_ETL/venv/lib/python3.10/site-packages/airflow/models/baseoperator.py", line 401, in wrapper
    return func(self, *args, **kwargs)
  File "/home/ongraph/Desktop/airflow/airflow_ETL/venv/lib/python3.10/site-packages/airflow/providers/http/operators/http.py", line 166, in execute
    return self.execute_sync(context=context)
  File "/home/ongraph/Desktop/airflow/airflow_ETL/venv/lib/python3.10/site-packages/airflow/providers/http/operators/http.py", line 170, in execute_sync
    response = self.hook.run(self.endpoint, self.data, self.headers, self.extra_options)
  File "/home/ongraph/Desktop/airflow/airflow_ETL/venv/lib/python3.10/site-packages/airflow/providers/http/hooks/http.py", line 188, in run
    return self.run_and_check(session, prepped_request, extra_options)
  File "/home/ongraph/Desktop/airflow/airflow_ETL/venv/lib/python3.10/site-packages/airflow/providers/http/hooks/http.py", line 244, in run_and_check
    raise ex
  File "/home/ongraph/Desktop/airflow/airflow_ETL/venv/lib/python3.10/site-packages/airflow/providers/http/hooks/http.py", line 236, in run_and_check
    response = session.send(prepped_request, **send_kwargs)
  File "/home/ongraph/Desktop/airflow/airflow_ETL/venv/lib/python3.10/site-packages/requests/sessions.py", line 703, in send
    r = adapter.send(request, **kwargs)
  File "/home/ongraph/Desktop/airflow/airflow_ETL/venv/lib/python3.10/site-packages/requests/adapters.py", line 519, in send
    raise ConnectionError(e, request=request)
requests.exceptions.ConnectionError: HTTPConnectionPool(host='https', port=80): Max retries exceeded with url: //chroniclingamerica.loc.gov/newspapers.json (Caused by NewConnectionError('<urllib3.connection.HTTPConnection object at 0x7611ecc48b50>: Failed to establish a new connection: [Errno -3] Temporary failure in name resolution'))
[2024-07-04T12:35:49.353+0530] {taskinstance.py:1206} INFO - Marking task as FAILED. dag_id=data_transformation, task_id=data_extraction, run_id=scheduled__2024-07-03T00:00:00+00:00, execution_date=20240703T000000, start_date=20240704T070549, end_date=20240704T070549
[2024-07-04T12:35:49.369+0530] {standard_task_runner.py:110} ERROR - Failed to execute job 3 for task data_extraction (HTTPConnectionPool(host='https', port=80): Max retries exceeded with url: //chroniclingamerica.loc.gov/newspapers.json (Caused by NewConnectionError('<urllib3.connection.HTTPConnection object at 0x7611ecc48b50>: Failed to establish a new connection: [Errno -3] Temporary failure in name resolution')); 90889)
[2024-07-04T12:35:49.410+0530] {local_task_job_runner.py:240} INFO - Task exited with return code 1
[2024-07-04T12:35:49.442+0530] {taskinstance.py:3503} INFO - 0 downstream tasks scheduled from follow-on schedule check
[2024-07-04T12:35:49.443+0530] {local_task_job_runner.py:222} INFO - ::endgroup::
