[2024-07-04T13:04:57.506+0530] {scheduler_job_runner.py:843} ERROR - Executor reports task instance <TaskInstance: data_transformation.data_extraction scheduled__2024-07-03T00:00:00+00:00 [queued]> finished (failed) although the task says it's queued. (Info: None) Was the task killed externally?
